import Exception from "exception"
import Future from "future"

var promise = Future.Promise[Number](f(resolve, reject) {
  if (true) {
    resolve(1000)
  } else {
    reject(Exception.Error("error"))
  }
})

promise
  .then(f(number) {
    print(number) // 1000
  })
  .catch(f(error) {
    print(error.message) // "error"
  })
  .finally(f(result) {
    print(result) // 1000 or Error instance
  })

-- stdout --
1000
1000